# Стандартные трейты для работы с ошибками

Rust предоставляет набор стандартных трейтов для работы с ошибками, которые позволяют создавать надежные и выразительные механизмы обработки ошибок. Эти трейты являются основой для паттерна обработки ошибок в Rust, основанного на типах `Result` и `Option`.

## Основные трейты для работы с ошибками

### `Error`

Трейт `Error` из модуля `std::error` является основным трейтом для типов ошибок в Rust:

```rust
pub trait Error: Debug + Display {
    fn source(&self) -> Option<&(dyn Error + 'static)> { ... }
    fn description(&self) -> &str { ... } // устаревший метод
    fn cause(&self) -> Option<&dyn Error> { ... } // устаревший метод
    fn provide<'a>(&'a self, request: &mut Request<'a>) { ... } // экспериментальный метод
}
```

Трейт `Error` требует, чтобы тип также реализовывал трейты `Debug` и `Display`. Он предоставляет метод `source()`, который возвращает ссылку на ошибку, вызвавшую текущую ошибку, если такая есть.

#### Пример реализации `Error`

```rust
use std::error::Error;
use std::fmt;
use std::io;

#[derive(Debug)]
enum AppError {
    Io(io::Error),
    Parse(std::num::ParseIntError),
    Custom(String),
}

impl fmt::Display for AppError {
    fn fmt(&self, f: &mut fmt::Formatter<'_>) -> fmt::Result {
        match self {
            AppError::Io(err) => write!(f, "Ошибка ввода-вывода: {}", err),
            AppError::Parse(err) => write!(f, "Ошибка парсинга: {}", err),
            AppError::Custom(msg) => write!(f, "Ошибка: {}", msg),
        }
    }
}

impl Error for AppError {
    fn source(&self) -> Option<&(dyn Error + 'static)> {
        match self {
            AppError::Io(err) => Some(err),
            AppError::Parse(err) => Some(err),
            AppError::Custom(_) => None,
        }
    }
}

fn main() -> Result<(), Box<dyn Error>> {
    let error = AppError::Custom(String::from("что-то пошло не так"));
    println!("Ошибка: {}", error);
    
    let io_error = io::Error::new(io::ErrorKind::NotFound, "файл не найден");
    let app_error = AppError::Io(io_error);
    println!("Ошибка: {}", app_error);
    
    if let Some(source) = app_error.source() {
        println!("Источник ошибки: {}", source);
    }
    
    Ok(())
}
```

### `From` и `Into`

Трейты `From` и `Into` используются для преобразования между типами ошибок:

```rust
pub trait From<T> {
    fn from(value: T) -> Self;
}

pub trait Into<T> {
    fn into(self) -> T;
}
```

Эти трейты особенно полезны при работе с оператором `?`, который автоматически преобразует ошибки с помощью `From`.
#### Пример использования `From` для преобразования ошибок

```rust
use std::error::Error;
use std::fmt;
use std::io;
use std::num::ParseIntError;

#[derive(Debug)]
enum AppError {
    Io(io::Error),
    Parse(ParseIntError),
    Custom(String),
}

impl fmt::Display for AppError {
    fn fmt(&self, f: &mut fmt::Formatter<'_>) -> fmt::Result {
        match self {
            AppError::Io(err) => write!(f, "Ошибка ввода-вывода: {}", err),
            AppError::Parse(err) => write!(f, "Ошибка парсинга: {}", err),
            AppError::Custom(msg) => write!(f, "Ошибка: {}", msg),
        }
    }
}

impl Error for AppError {
    fn source(&self) -> Option<&(dyn Error + 'static)> {
        match self {
            AppError::Io(err) => Some(err),
            AppError::Parse(err) => Some(err),
            AppError::Custom(_) => None,
        }
    }
}

impl From<io::Error> for AppError {
    fn from(err: io::Error) -> Self {
        AppError::Io(err)
    }
}

impl From<ParseIntError> for AppError {
    fn from(err: ParseIntError) -> Self {
        AppError::Parse(err)
    }
}

fn read_and_parse() -> Result<i32, AppError> {
    let mut input = String::new();
    io::stdin().read_line(&mut input)?; // io::Error автоматически преобразуется в AppError
    let number = input.trim().parse::<i32>()?; // ParseIntError автоматически преобразуется в AppError
    
    if number < 0 {
        return Err(AppError::Custom(String::from("Число должно быть положительным")));
    }
    
    Ok(number)
}

fn main() {
    match read_and_parse() {
        Ok(number) => println!("Вы ввели: {}", number),
        Err(err) => {
            println!("Произошла ошибка: {}", err);
            if let Some(source) = err.source() {
                println!("Источник ошибки: {}", source);
            }
        }
    }
}
```

### `Debug` и `Display`

Трейты `Debug` и `Display` используются для форматирования ошибок:

```rust
pub trait Debug {
    fn fmt(&self, f: &mut Formatter<'_>) -> Result<(), Error>;
}

pub trait Display {
    fn fmt(&self, f: &mut Formatter<'_>) -> Result<(), Error>;
}
```

Трейт `Debug` используется для отладочного форматирования, а трейт `Display` — для пользовательского форматирования.

#### Пример реализации `Debug` и `Display`

```rust
use std::fmt;

#[derive(Debug)]
struct CustomError {
    message: String,
    line: u32,
    column: u32,
}

impl fmt::Display for CustomError {
    fn fmt(&self, f: &mut fmt::Formatter<'_>) -> fmt::Result {
        write!(f, "Ошибка: {} (строка {}, столбец {})", self.message, self.line, self.column)
    }
}

fn main() {
    let error = CustomError {
        message: String::from("неожиданный символ"),
        line: 10,
        column: 5,
    };
    
    println!("Отладочный вывод: {:?}", error);
    println!("Пользовательский вывод: {}", error);
    println!("Красивый отладочный вывод: {:#?}", error);
}
```

## Типы `Result` и `Option`

Типы `Result` и `Option` являются основой для обработки ошибок в Rust.

### `Result<T, E>`

Тип `Result<T, E>` представляет результат операции, которая может завершиться ошибкой:

```rust
pub enum Result<T, E> {
    Ok(T),
    Err(E),
}
```

#### Пример использования `Result`

```rust
use std::fs::File;
use std::io::{self, Read};

fn read_file(path: &str) -> Result<String, io::Error> {
    let mut file = File::open(path)?;
    let mut content = String::new();
    file.read_to_string(&mut content)?;
    Ok(content)
}

fn main() {
    match read_file("example.txt") {
        Ok(content) => println!("Содержимое файла:\n{}", content),
        Err(err) => println!("Ошибка при чтении файла: {}", err),
    }
}
```

### `Option<T>`

Тип `Option<T>` представляет значение, которое может отсутствовать:

```rust
pub enum Option<T> {
    Some(T),
    None,
}
```

#### Пример использования `Option`

```rust
fn find_user(id: u32) -> Option<String> {
    let users = vec![
        (1, "Алиса"),
        (2, "Боб"),
        (3, "Чарли"),
    ];
    
    users.iter()
        .find(|&&(user_id, _)| user_id == id)
        .map(|&(_, name)| name.to_string())
}

fn main() {
    match find_user(2) {
        Some(name) => println!("Пользователь найден: {}", name),
        None => println!("Пользователь не найден"),
    }
    
    // Использование метода unwrap_or
    let name = find_user(4).unwrap_or_else(|| String::from("Неизвестный пользователь"));
    println!("Имя: {}", name);
}
```

## Оператор `?`

Оператор `?` используется для краткой обработки ошибок. Он автоматически возвращает ошибку из функции, если результат операции — `Err` или `None`.

### Пример использования оператора `?` с `Result`

```rust
use std::fs::File;
use std::io::{self, Read};

fn read_file(path: &str) -> Result<String, io::Error> {
    let mut file = File::open(path)?; // Возвращает ошибку, если файл не удалось открыть
    let mut content = String::new();
    file.read_to_string(&mut content)?; // Возвращает ошибку, если не удалось прочитать файл
    Ok(content)
}

fn main() {
    match read_file("example.txt") {
        Ok(content) => println!("Содержимое файла:\n{}", content),
        Err(err) => println!("Ошибка при чтении файла: {}", err),
    }
}
```

### Пример использования оператора `?` с `Option`

```rust
fn first_even(numbers: &[i32]) -> Option<i32> {
    let first = numbers.get(0)?; // Возвращает None, если массив пуст
    if first % 2 == 0 {
        Some(*first)
    } else {
        None
    }
}

fn main() {
    let numbers = vec![1, 2, 3, 4, 5];
    match first_even(&numbers) {
        Some(n) => println!("Первое четное число: {}", n),
        None => println!("Четных чисел нет"),
    }
    
    let empty: Vec<i32> = vec![];
    match first_even(&empty) {
        Some(n) => println!("Первое четное число: {}", n),
        None => println!("Четных чисел нет"),
    }
}
```
## Создание собственных типов ошибок

Создание собственных типов ошибок позволяет более точно выражать ошибки, которые могут возникнуть в вашем коде.

### Пример создания собственного типа ошибки

```rust
use std::error::Error;
use std::fmt;
use std::io;
use std::num::ParseIntError;

#[derive(Debug)]
enum ConfigError {
    IoError(io::Error),
    ParseError(ParseIntError),
    MissingField(String),
    InvalidValue(String, String),
}

impl fmt::Display for ConfigError {
    fn fmt(&self, f: &mut fmt::Formatter<'_>) -> fmt::Result {
        match self {
            ConfigError::IoError(err) => write!(f, "Ошибка ввода-вывода: {}", err),
            ConfigError::ParseError(err) => write!(f, "Ошибка парсинга: {}", err),
            ConfigError::MissingField(field) => write!(f, "Отсутствует обязательное поле: {}", field),
            ConfigError::InvalidValue(field, value) => write!(f, "Недопустимое значение {} для поля {}", value, field),
        }
    }
}

impl Error for ConfigError {
    fn source(&self) -> Option<&(dyn Error + 'static)> {
        match self {
            ConfigError::IoError(err) => Some(err),
            ConfigError::ParseError(err) => Some(err),
            ConfigError::MissingField(_) => None,
            ConfigError::InvalidValue(_, _) => None,
        }
    }
}

impl From<io::Error> for ConfigError {
    fn from(err: io::Error) -> Self {
        ConfigError::IoError(err)
    }
}

impl From<ParseIntError> for ConfigError {
    fn from(err: ParseIntError) -> Self {
        ConfigError::ParseError(err)
    }
}

fn parse_config(content: &str) -> Result<Config, ConfigError> {
    let mut config = Config::default();
    
    for line in content.lines() {
        let line = line.trim();
        if line.is_empty() || line.starts_with('#') {
            continue;
        }
        
        let parts: Vec<&str> = line.splitn(2, '=').collect();
        if parts.len() != 2 {
            return Err(ConfigError::InvalidValue(line.to_string(), "не является парой ключ=значение".to_string()));
        }
        
        let key = parts[0].trim();
        let value = parts[1].trim();
        
        match key {
            "host" => config.host = value.to_string(),
            "port" => config.port = value.parse()?,
            "max_connections" => config.max_connections = value.parse()?,
            "timeout" => config.timeout = value.parse()?,
            _ => return Err(ConfigError::InvalidValue(key.to_string(), "неизвестный ключ".to_string())),
        }
    }
    
    if config.host.is_empty() {
        return Err(ConfigError::MissingField("host".to_string()));
    }
    
    Ok(config)
}

#[derive(Debug, Default)]
struct Config {
    host: String,
    port: u16,
    max_connections: usize,
    timeout: u64,
}

fn main() -> Result<(), Box<dyn Error>> {
    let config_content = r#"
        # Конфигурация сервера
        host = localhost
        port = 8080
        max_connections = 100
        timeout = 30
    "#;
    
    let config = parse_config(config_content)?;
    println!("Конфигурация: {:?}", config);
    
    let invalid_config = r#"
        # Конфигурация с ошибкой
        host = localhost
        port = invalid
    "#;
    
    match parse_config(invalid_config) {
        Ok(config) => println!("Конфигурация: {:?}", config),
        Err(err) => {
            println!("Ошибка при парсинге конфигурации: {}", err);
            if let Some(source) = err.source() {
                println!("Источник ошибки: {}", source);
            }
        }
    }
    
    Ok(())
}
```

## Паттерны обработки ошибок

### Распространение ошибок

Распространение ошибок — это паттерн, при котором функция возвращает ошибку вызывающей функции, вместо того чтобы обрабатывать ее самостоятельно.

```rust
use std::error::Error;
use std::fs::File;
use std::io::{self, Read};

fn read_file(path: &str) -> Result<String, io::Error> {
    let mut file = File::open(path)?;
    let mut content = String::new();
    file.read_to_string(&mut content)?;
    Ok(content)
}

fn process_file(path: &str) -> Result<(), Box<dyn Error>> {
    let content = read_file(path)?;
    println!("Содержимое файла:\n{}", content);
    Ok(())
}

fn main() {
    match process_file("example.txt") {
        Ok(()) => println!("Файл успешно обработан"),
        Err(err) => println!("Ошибка при обработке файла: {}", err),
    }
}
```

### Преобразование ошибок

Преобразование ошибок — это паттерн, при котором ошибки одного типа преобразуются в ошибки другого типа.

```rust
use std::error::Error;
use std::fmt;
use std::fs::File;
use std::io::{self, Read};

#[derive(Debug)]
enum AppError {
    FileError(String, io::Error),
    ParseError(String),
}

impl fmt::Display for AppError {
    fn fmt(&self, f: &mut fmt::Formatter<'_>) -> fmt::Result {
        match self {
            AppError::FileError(path, err) => write!(f, "Ошибка при работе с файлом {}: {}", path, err),
            AppError::ParseError(msg) => write!(f, "Ошибка при парсинге: {}", msg),
        }
    }
}

impl Error for AppError {
    fn source(&self) -> Option<&(dyn Error + 'static)> {
        match self {
            AppError::FileError(_, err) => Some(err),
            AppError::ParseError(_) => None,
        }
    }
}

fn read_file(path: &str) -> Result<String, AppError> {
    let mut file = File::open(path)
        .map_err(|err| AppError::FileError(path.to_string(), err))?;
    
    let mut content = String::new();
    file.read_to_string(&mut content)
        .map_err(|err| AppError::FileError(path.to_string(), err))?;
    
    Ok(content)
}

fn parse_number(content: &str) -> Result<i32, AppError> {
    content.trim().parse::<i32>()
        .map_err(|_| AppError::ParseError(format!("Не удалось преобразовать '{}' в число", content)))
}

fn process_file(path: &str) -> Result<i32, AppError> {
    let content = read_file(path)?;
    let number = parse_number(&content)?;
    Ok(number)
}

fn main() {
    match process_file("number.txt") {
        Ok(number) => println!("Число из файла: {}", number),
        Err(err) => {
            println!("Ошибка: {}", err);
            if let Some(source) = err.source() {
                println!("Источник ошибки: {}", source);
            }
        }
    }
}
```

### Обработка ошибок с помощью `match`

Обработка ошибок с помощью `match` — это паттерн, при котором различные типы ошибок обрабатываются по-разному.

```rust
use std::fs::File;
use std::io::{self, Read};

fn read_file(path: &str) -> Result<String, io::Error> {
    let mut file = File::open(path)?;
    let mut content = String::new();
    file.read_to_string(&mut content)?;
    Ok(content)
}

fn main() {
    match read_file("example.txt") {
        Ok(content) => println!("Содержимое файла:\n{}", content),
        Err(err) => match err.kind() {
            io::ErrorKind::NotFound => println!("Файл не найден"),
            io::ErrorKind::PermissionDenied => println!("Нет прав доступа к файлу"),
            _ => println!("Ошибка при чтении файла: {}", err),
        },
    }
}
```

### Обработка ошибок с помощью комбинаторов

Обработка ошибок с помощью комбинаторов — это паттерн, при котором используются методы типов `Result` и `Option` для обработки ошибок без использования `match`.

```rust
use std::fs::File;
use std::io::{self, Read};

fn read_file(path: &str) -> Result<String, io::Error> {
    let mut file = File::open(path)?;
    let mut content = String::new();
    file.read_to_string(&mut content)?;
    Ok(content)
}

fn main() {
    let content = read_file("example.txt")
        .unwrap_or_else(|err| {
            println!("Ошибка при чтении файла: {}", err);
            String::new()
        });
    
    println!("Содержимое файла (или пустая строка в случае ошибки):\n{}", content);
    
    // Альтернативный подход с использованием map и unwrap_or
    let content = read_file("example.txt")
        .map(|s| s.to_uppercase())
        .unwrap_or_else(|_| String::from("Файл не найден или не удалось прочитать"));
    
    println!("Содержимое файла в верхнем регистре (или сообщение об ошибке):\n{}", content);
}
```

## Практические примеры использования трейтов для работы с ошибками

### Пример: Парсинг конфигурационного файла

```rust
use std::error::Error;
use std::fmt;
use std::fs::File;
use std::io::{self, Read};
use std::num::ParseIntError;
use std::str::FromStr;

#[derive(Debug)]
enum ConfigError {
    Io(io::Error),
    Parse(ParseIntError),
    Format(String),
    Missing(String),
    Invalid(String),
}

impl fmt::Display for ConfigError {
    fn fmt(&self, f: &mut fmt::Formatter<'_>) -> fmt::Result {
        match self {
            ConfigError::Io(err) => write!(f, "Ошибка ввода-вывода: {}", err),
            ConfigError::Parse(err) => write!(f, "Ошибка парсинга: {}", err),
            ConfigError::Format(msg) => write!(f, "Ошибка формата: {}", msg),
            ConfigError::Missing(field) => write!(f, "Отсутствует обязательное поле: {}", field),
            ConfigError::Invalid(msg) => write!(f, "Недопустимое значение: {}", msg),
        }
    }
}

impl Error for ConfigError {
    fn source(&self) -> Option<&(dyn Error + 'static)> {
        match self {
            ConfigError::Io(err) => Some(err),
            ConfigError::Parse(err) => Some(err),
            ConfigError::Format(_) => None,
            ConfigError::Missing(_) => None,
            ConfigError::Invalid(_) => None,
        }
    }
}

impl From<io::Error> for ConfigError {
    fn from(err: io::Error) -> Self {
        ConfigError::Io(err)
    }
}

impl From<ParseIntError> for ConfigError {
    fn from(err: ParseIntError) -> Self {
        ConfigError::Parse(err)
    }
}

#[derive(Debug, Default)]
struct ServerConfig {
    host: String,
    port: u16,
    workers: usize,
    timeout: u64,
    debug: bool,
}

impl ServerConfig {
    fn from_file(path: &str) -> Result<Self, ConfigError> {
        let mut file = File::open(path)?;
        let mut content = String::new();
        file.read_to_string(&mut content)?;
        
        Self::from_str(&content)
    }
}

impl FromStr for ServerConfig {
    type Err = ConfigError;
    
    fn from_str(s: &str) -> Result<Self, Self::Err> {
        let mut config = ServerConfig::default();
        
        for line in s.lines() {
            let line = line.trim();
            if line.is_empty() || line.starts_with('#') {
                continue;
            }
            
            let parts: Vec<&str> = line.splitn(2, '=').collect();
            if parts.len() != 2 {
                return Err(ConfigError::Format(format!("Неверный формат строки: {}", line)));
            }
            
            let key = parts[0].trim();
            let value = parts[1].trim();
            
            match key {
                "host" => config.host = value.to_string(),
                "port" => config.port = value.parse()?,
                "workers" => config.workers = value.parse()?,
                "timeout" => config.timeout = value.parse()?,
                "debug" => config.debug = match value.to_lowercase().as_str() {
                    "true" | "yes" | "1" => true,
                    "false" | "no" | "0" => false,
                    _ => return Err(ConfigError::Invalid(format!("Недопустимое значение для debug: {}", value))),
                },
                _ => return Err(ConfigError::Invalid(format!("Неизвестный ключ: {}", key))),
            }
        }
        
        if config.host.is_empty() {
            return Err(ConfigError::Missing("host".to_string()));
        }
        
        if config.port == 0 {
            return Err(ConfigError::Missing("port".to_string()));
        }
        
        Ok(config)
    }
}

fn main() -> Result<(), Box<dyn Error>> {
    let config = ServerConfig::from_file("server.conf")
        .or_else(|err| {
            println!("Ошибка при чтении конфигурации: {}", err);
            println!("Используем конфигурацию по умолчанию");
            
            Ok(ServerConfig {
                host: String::from("localhost"),
                port: 8080,
                workers: 4,
                timeout: 30,
                debug: false,
            })
        })?;
    
    println!("Конфигурация сервера: {:?}", config);
    
    Ok(())
}
```

## Заключение

Стандартные трейты для работы с ошибками в Rust предоставляют мощные инструменты для создания надежных и выразительных механизмов обработки ошибок. Они позволяют создавать собственные типы ошибок, преобразовывать ошибки между различными типами и обрабатывать ошибки различными способами.

Основные преимущества использования стандартных трейтов для работы с ошибками:

1. **Типобезопасность**: Ошибки обрабатываются на уровне типов, что позволяет компилятору проверять корректность обработки ошибок.
2. **Выразительность**: Типы `Result` и `Option` позволяют явно выражать возможность ошибки или отсутствия значения.
3. **Гибкость**: Трейты `Error`, `From` и `Into` позволяют создавать гибкие механизмы обработки ошибок.
4. **Краткость**: Оператор `?` позволяет кратко выражать распространение ошибок.

Правильное использование стандартных трейтов для работы с ошибками является важной частью идиоматического кода на Rust и помогает создавать более надежные и понятные программы.